<?xml version="1.0"?>
<robot name="bouncy" xmlns:xacro="http://www.ros.org/wiki/xacro">
	<xacro:include filename="/home/oem/ros2_ws/src/bouncy_bot/urdf/bouncy.ign"/>

    <!-- Parameters -->
    <xacro:property name="ball_mass" value="1" />
    <xacro:property name="engin_mass" value="10" />
    <xacro:property name="PI" value="1.5707" />
    <xacro:property name="engin_Zpose" value="0.1224" />
    <xacro:property name="enginZpose" value="-0.0408" />
  <link name="outer_ball">
    <inertial>
        <mass value="${ball_mass}" />
        <inertia ixx="0.064" ixy="0" ixz="0" iyy="0.064" iyz="0" izz="0.064" />
    </inertial>
	<self_collide>true</self_collide>
	<collision name="collision">
        <geometry>
            <sphere radius="0.44" />
        </geometry>
		<surface>
			<poissons_ratio> 0.49 </poissons_ratio>
			<elastic_modulus> 0.3 </elastic_modulus>
        	<contact>
        	  <ode>
        	    <max_vel>1</max_vel>
        	  </ode>
        	</contact>
        </surface>
    </collision>
    <visual>
        <geometry>
        	<sphere radius="0.44" />
	    </geometry>
    </visual>
  </link>

		<!-- Joint - rotation_engin / pull_engin -->
	<joint name="joint_ rotation_engin_engin" type="prismatic">
	    <origin rpy="0 0 0" xyz="0 0 0"/>
	    <child link="pull_engin" />
	    <parent link="rotation_engin" />
	    <axis rpy="0 0 0" xyz="0 0 1" />
	    <limit upper="0" lower="-0.36" effort="10000" velocity="1000" />
	</joint>

	<!-- Link - pull_engin -->
  <link name="pull_engin">
    <inertial>
        <mass value="${engin_mass}" />
        <inertia ixx="0.001" ixy="0" ixz="0" iyy="0.001" iyz="0" izz="0.001" />
    </inertial>
	<self_collide>true</self_collide>
	<collision name="collision">
        <geometry>
            <sphere radius="0.05" />
        </geometry>
		<surface>
        	<contact>
        	  <ode>
        	    <max_vel>1</max_vel>
        	  </ode>
        	</contact>
        </surface>
    </collision>
    <visual>
        <geometry>
        	<sphere radius="0.05" />
	    </geometry>
    </visual>
  </link>


		<!-- Joint - outer_ball /  rotation engin-->
	<joint name="joint_ outer_ball_rotation_engin"  type="continuous">
	    <origin rpy="0 0 0" xyz="0 0 0" />
	    <child link="rotation_engin" />
	    <parent link="outer_ball" />
	    <axis rpy="0 0 0" xyz="0 0 1" />
	    <limit effort="10000" velocity="1000" />
	    <joint_properties damping="1.0" friction="1.0" />
	</joint>

    <link name="rotation_engin">
        <inertial>
            <mass value="${engin_mass}" />
            <origin xyz="0 0 0" rpy="0 0 0" />
            <inertia ixx="0.0538" ixy="0" ixz="0" iyy="0.0538" iyz="0" izz="0.00106" />
        </inertial>

        <collision>
            <geometry>
                <box size="0.08 0.08 0.8" />
            </geometry>
        </collision>

        <visual>
            <geometry>
                <box size="0.08 0.08 0.8" />
			</geometry>
            <material name="Blue">
                <color rgba="0 0 0.5 1" />
            </material>
        </visual>
    </link>

		<!-- Joint - pull_engin /  rotating_arms-->
	<joint name="joint_ outer_ball_rotating_arm1"  type="continuous">
	    <origin rpy="0 0 0" xyz="-0.055 0 0" />
	    <child link="rotating_arm1" />
	    <parent link="pull_engin" />
	    <axis rpy="0 0 0" xyz="1 0 0" />
	    <limit effort="10000" velocity="1000" />
	    <joint_properties damping="1.0" friction="1.0" />
	</joint>

	<link name="rotating_arm1">
	  <inertial>
	    <mass value="${engin_mass}" />
	    <origin xyz="-0 0 0.18" rpy="0 0 0" />
	    <inertia ixx="0.0116" ixy="0" ixz="0" iyy="0.0108" iyz="0" izz="0.000842" />
	  </inertial>
	  <collision>
	    <origin xyz="-0 0 0.18" rpy="0 0 0" />
	    <geometry>
	      <box size="0.01 0.1 0.36" />
	    </geometry>
	  </collision>
	  <visual>
	    <origin xyz="-0 0 0.18" rpy="0 0 0" />
	    <geometry>
	      <box size="0.01 0.1 0.36" />
	    </geometry>
	  </visual>
	</link>


	<joint name="joint_ outer_ball_rotating_arm2"  type="continuous">
	    <origin rpy="0 0 0" xyz="0.055 0 0" />
	    <child link="rotating_arm2" />
	    <parent link="pull_engin" />
	    <axis rpy="0 0 0" xyz="1 0 0" />
	    <limit effort="10000" velocity="1000" />
	    <joint_properties damping="1.0" friction="1.0" />
	</joint>

	<link name="rotating_arm2">
	  <inertial>
	    <mass value="${engin_mass}" />
	    <origin xyz="-0 0 0.18" rpy="0 0 0" />
	    <inertia ixx="0.0116" ixy="0" ixz="0" iyy="0.0108" iyz="0" izz="0.000842" />
	  </inertial>
	  <collision>
	    <origin xyz="-0 0 0.18" rpy="0 0 0" />
	    <geometry>
	      <box size="0.01 0.1 0.36" />
	    </geometry>
	  </collision>
	  <visual>
	    <origin xyz="-0 0 0.18" rpy="0 0 0" />
	    <geometry>
	      <box size="0.01 0.1 0.36" />
	    </geometry>
	    <material name="grey">
	      <color rgba="0.5 0.5 0.5 1" />
	    </material>
	  </visual>
	</link>

</robot>
