<sdf version='1.9'>
  <model name='bouncy'>


    <link name='outer_ball'>
      <inertial>
        <pose>0 0 0 0 0 0</pose>
        <mass>0.5</mass>
        <inertia>
          <ixx>0.064000000000000001</ixx>
          <ixy>0</ixy>
          <ixz>0</ixz>
          <iyy>0.064000000000000001</iyy>
          <iyz>0</iyz>
          <izz>0.064000000000000001</izz>
        </inertia>
      </inertial>
      <collision name='outer_ball_collision'>
        <pose>0 0 0 0 0 0</pose>
        <geometry>
          <sphere>
            <radius>0.44</radius>
          </sphere>
        </geometry>
        <surface>
          <bounce>
            <restitution_coefficient>1</restitution_coefficient>
            <threshold>0.10000000000000001</threshold>
          </bounce>
          <friction>
            <torsional>
              <coefficient>0.20000000000000001</coefficient>
              <surface_radius>0.5</surface_radius>
              <use_patch_radius>false</use_patch_radius>
            </torsional>
            <ode/>
          </friction>
          <contact>
            <poissons_ratio>0.48999999999999999</poissons_ratio>
            <elastic_modulus>0.29999999999999999</elastic_modulus>
            <ode/>
          </contact>
        </surface>
      </collision>
      <visual name='outer_ball_visual'>
        <pose>0 0 0 0 0 0</pose>
        <geometry>
          <sphere>
            <radius>0.44</radius>
          </sphere>
        </geometry>
        <material>
          <ambient>0.3 0 0.3 0.5</ambient>
          <diffuse>0.3 0 0.3 0.5</diffuse>
          <specular>0 0 0 0.5</specular>
          <emissive>0 0 0 0.5</emissive>
        </material>
      </visual>
      <velocity_decay>
        <linear>0.10000000000000001</linear>
        <angular>0.10000000000000001</angular>
      </velocity_decay>
    </link>


    <joint name='joint_outer_ball_rotation_engin' type='revolute'>
      <pose relative_to='outer_ball'>0 0 0 0 0 0</pose>
      <parent>outer_ball</parent>
      <child>rotation_engin</child>
      <axis>
        <xyz>0 0 1</xyz>
        <limit>
          <effort>10000</effort>
          <velocity>5</velocity>
          <lower>-10000000000000000</lower>
          <upper>10000000000000000</upper>
        </limit>
        <dynamics>
          <spring_reference>0</spring_reference>
          <spring_stiffness>0</spring_stiffness>
        </dynamics>
      </axis>
    </joint>
    <link name='rotation_engin'>
      <pose relative_to='joint_outer_ball_rotation_engin'>0 0 0 0 0 0</pose>
      <inertial>
        <pose>0 0 0 0 0 0</pose>
        <mass>1.2</mass>
        <inertia>
          <ixx>0.053800000000000001</ixx>
          <ixy>0</ixy>
          <ixz>0</ixz>
          <iyy>0.053800000000000001</iyy>
          <iyz>0</iyz>
          <izz>0.00106</izz>
        </inertia>
      </inertial>
      <collision name='rotation_engin_collision'>
        <pose>0 0 0 0 0 0</pose>
        <geometry>
          <box>
            <size>0.08 0.08 0.87</size>
          </box>
        </geometry>
        <surface>
          <contact>
            <ode/>
          </contact>
          <friction>
            <ode/>
          </friction>
        </surface>
      </collision>
      <visual name='rotation_engin_visual'>
        <pose>0 0 0 0 0 0</pose>
        <geometry>
          <box>
            <size>0.08 0.08 0.87</size>
          </box>
        </geometry>
        <material>
          <ambient>0 0.5 0.3 1</ambient>
          <diffuse>0 0.5 0.3 1</diffuse>
          <specular>0 0 0 1</specular>
          <emissive>0 0 0 1</emissive>
        </material>
      </visual>
    </link>
    <joint name='joint_rotation_engin_pull_engin' type='prismatic'>
      <pose relative_to='rotation_engin'>0 0 0 0 0 0</pose>
      <parent>rotation_engin</parent>
      <child>pull_engin</child>
      <axis>
        <xyz>0 0 1</xyz>
        <limit>
          <lower>-0.40000000000000002</lower>
          <upper>0</upper>
          <effort>10000</effort>
          <velocity>1000</velocity>
        </limit>
        <dynamics>
          <spring_reference>0</spring_reference>
          <spring_stiffness>0</spring_stiffness>
        </dynamics>
      </axis>
    </joint>
    <link name='pull_engin'>
      <pose relative_to='joint_rotation_engin_pull_engin'>0 0 0 0 0 0</pose>
      <inertial>
        <pose>0 0 0 0 0 0</pose>
        <mass>1.2</mass>
        <inertia>
          <ixx>0.001</ixx>
          <ixy>0</ixy>
          <ixz>0</ixz>
          <iyy>0.001</iyy>
          <iyz>0</iyz>
          <izz>0.001</izz>
        </inertia>
      </inertial>
      <collision name='pull_engin_fixed_joint_lump__collision_collision'>
        <pose>0 0 0 0 0 0</pose>
        <geometry>
          <sphere>
            <radius>0.050000000000000003</radius>
          </sphere>
        </geometry>
      </collision>
      <visual name='pull_engin_visual'>
        <pose>0 0 0 0 0 0</pose>
        <geometry>
          <sphere>
            <radius>0.050000000000000003</radius>
          </sphere>
        </geometry>
      </visual>
    </link>
    <joint name='joint_pull_engin_rotating_arm1' type='revolute'>
      <pose relative_to='pull_engin'>-0.055 0 0 3.141 0 0</pose>
      <parent>pull_engin</parent>
      <child>rotating_arm1</child>
      <axis>
        <xyz>1 0 0</xyz>
        <limit>
          <effort>10000</effort>
          <velocity>100</velocity>
          <lower>-10000000000000000</lower>
          <upper>10000000000000000</upper>
        </limit>
        <dynamics>
          <spring_reference>0</spring_reference>
          <spring_stiffness>0</spring_stiffness>
        </dynamics>
      </axis>
    </joint>
    <link name='rotating_arm1'>
      <pose relative_to='joint_pull_engin_rotating_arm1'>0 0 0 0 0 0</pose>
      <inertial>
        <pose>0 0 0.18 0 0 0</pose>
        <mass>3.2000000000000002</mass>
        <inertia>
          <ixx>0.011599999999999999</ixx>
          <ixy>0</ixy>
          <ixz>0</ixz>
          <iyy>0.010800000000000001</iyy>
          <iyz>0</iyz>
          <izz>0.00084199999999999998</izz>
        </inertia>
      </inertial>
      <collision name='rotating_arm1_collision'>
        <pose>0 0 0.18 0 0 0</pose>
        <geometry>
          <box>
            <size>0.01 0.1 0.36</size>
          </box>
        </geometry>
        <surface>
          <contact>
            <ode/>
          </contact>
          <friction>
            <ode/>
          </friction>
        </surface>
      </collision>
      <visual name='rotating_arm1_visual'>
        <pose>0 0 0.18 0 0 0</pose>
        <geometry>
          <box>
            <size>0.01 0.1 0.36</size>
          </box>
        </geometry>
        <material>
          <ambient>0.5 0.5 0.5 1</ambient>
          <diffuse>0.5 0.5 0.5 1</diffuse>
          <specular>0 0 0 1</specular>
          <emissive>0 0 0 1</emissive>
        </material>
      </visual>
    </link>
    <joint name='joint_pull_engin_rotating_arm2' type='revolute'>
      <pose relative_to='pull_engin'>0.055 0 0 3.141 0 0</pose>
      <parent>pull_engin</parent>
      <child>rotating_arm2</child>
      <axis>
        <xyz>1 0 0</xyz>
        <limit>
          <effort>10000</effort>
          <velocity>100</velocity>
          <lower>-10000000000000000</lower>
          <upper>10000000000000000</upper>
        </limit>
        <dynamics>
          <spring_reference>0</spring_reference>
          <spring_stiffness>0</spring_stiffness>
        </dynamics>
      </axis>
    </joint>
    <link name='rotating_arm2'>
      <pose relative_to='joint_pull_engin_rotating_arm2'>0 0 0 0 0 0</pose>
      <inertial>
        <pose>0 0 0.18 0 0 0</pose>
        <mass>3.2000000000000002</mass>
        <inertia>
          <ixx>0.011599999999999999</ixx>
          <ixy>0</ixy>
          <ixz>0</ixz>
          <iyy>0.010800000000000001</iyy>
          <iyz>0</iyz>
          <izz>0.00084199999999999998</izz>
        </inertia>
      </inertial>
      <collision name='rotating_arm2_collision'>
        <pose>0 0 0.18 0 0 0</pose>
        <geometry>
          <box>
            <size>0.01 0.1 0.36</size>
          </box>
        </geometry>
        <surface>
          <contact>
            <ode/>
          </contact>
          <friction>
            <ode/>
          </friction>
        </surface>
      </collision>
      <visual name='rotating_arm2_visual'>
        <pose>0 0 0.18 0 0 0</pose>
        <geometry>
          <box>
            <size>0.01 0.1 0.36</size>
          </box>
        </geometry>
        <material>
          <ambient>0.5 0.5 0.5 1</ambient>
          <diffuse>0.5 0.5 0.5 1</diffuse>
          <specular>0 0 0 1</specular>
          <emissive>0 0 0 1</emissive>
        </material>
      </visual>
    </link>
    <plugin name='gz::sim::systems::JointPositionController' filename='ignition-gazebo-joint-position-controller-system'>
      <joint_name>joint_rotation_engin_pull_engin</joint_name>
      <topic>jump_cmd</topic>
      <p_gain>50</p_gain>
      <i_gain>1.0</i_gain>
      <d_gain>0.0</d_gain>
      <i_max>1</i_max>
      <i_min>-1</i_min>
      <cmd_max>1000</cmd_max>
      <cmd_min>-1000</cmd_min>
    </plugin>
    <plugin name='gz::sim::systems::JointController' filename='ignition-gazebo-joint-controller-system'>
      <topic>rot1_cmd</topic>
      <initial_velocity>0</initial_velocity>
      <joint_name>joint_pull_engin_rotating_arm1</joint_name>
      <use_force_commands>false</use_force_commands>
    </plugin>
    <plugin name='gz::sim::systems::JointController' filename='ignition-gazebo-joint-controller-system'>
      <topic>rot2_cmd</topic>
      <initial_velocity>0</initial_velocity>
      <joint_name>joint_pull_engin_rotating_arm2</joint_name>
      <use_force_commands>false</use_force_commands>
    </plugin>
    <plugin name='gz::sim::systems::JointPositionController' filename='ignition-gazebo-joint-position-controller-system'>
      <joint_name>joint_outer_ball_rotation_engin</joint_name>
      <topic>turn_cmd</topic>
      <p_gain>1</p_gain>
      <i_gain>0.01</i_gain>
      <d_gain>0.3</d_gain>
      <i_max>1</i_max>
      <i_min>-1</i_min>
      <cmd_max>1000</cmd_max>
      <cmd_min>-1000</cmd_min>
    </plugin>
    <plugin name='gz::sim::systems::PosePublisher' filename='ignition-gazebo-pose-publisher-system'>
      <publish_link_pose>true</publish_link_pose>
      <publish_collision_pose>false</publish_collision_pose>
      <publish_visual_pose>false</publish_visual_pose>
      <publish_nested_model_pose>false</publish_nested_model_pose>
      <use_pose_vector_msg>true</use_pose_vector_msg>
      <update_frequency>1</update_frequency>
    </plugin>
    <plugin name='gz::sim::systems::PosePublisher' filename='ignition-gazebo-pose-publisher-system'>
      <publish_link_pose>true</publish_link_pose>
      <publish_collision_pose>false</publish_collision_pose>
      <publish_visual_pose>false</publish_visual_pose>
      <publish_nested_model_pose>false</publish_nested_model_pose>
      <use_pose_vector_msg>true</use_pose_vector_msg>
    </plugin>
  </model>
</sdf>
