<?xml version="1.0" ?>
<!-- =================================================================================== -->
<!-- |    This document was autogenerated by xacro from bouncy.xacro                   | -->
<!-- |    EDITING THIS FILE BY HAND IS NOT RECOMMENDED                                 | -->
<!-- =================================================================================== -->
<robot name="bouncy">
  <gazebo reference="outer_ball">
    <visual>
      <material>
        <ambient>0.3 0.0 0.3 0.5</ambient>
        <diffuse>0.3 0.0 0.3 0.5</diffuse>
        <specular>0.0 0.0 0.0 0.5</specular>
        <emissive>0.0 0.0 0.0 0.5</emissive>
      </material>
    </visual>
    <velocity_decay>
      <linear>0.1</linear>
      <angular>0.1</angular>
    </velocity_decay>
    <collision>
      <surface>
        <bounce>
          <restitution_coefficient>1</restitution_coefficient>
          <threshold>0.1 </threshold>
        </bounce>
        <friction>
          <torsional>
            <coefficient>0.2</coefficient>
            <surface_radius>0.5</surface_radius>
            <use_patch_radius>false</use_patch_radius>
          </torsional>
        </friction>
        <contact>
          <poissons_ratio>0.49</poissons_ratio>
          <elastic_modulus>0.3</elastic_modulus>
        </contact>
      </surface>
    </collision>
  </gazebo>
  <gazebo reference="rotation_engin">
    <visual>
      <material>
        <ambient>0.0 0.5 0.3 1.0</ambient>
        <diffuse>0.0 0.5 0.3 1.0</diffuse>
        <specular>0.0 0.0 0.0 1.0</specular>
        <emissive>0.0 0.0 0.0 1.0</emissive>
      </material>
    </visual>
  </gazebo>
  <gazebo reference="rotating_arm2">
    <visual>
      <material>
        <ambient>0.5 0.5 0.5 1.0</ambient>
        <diffuse>0.5 0.5 0.5 1.0</diffuse>
        <specular>0.0 0.0 0.0 1.0</specular>
        <emissive>0.0 0.0 0.0 1.0</emissive>
      </material>
    </visual>
  </gazebo>
  <gazebo reference="rotating_arm1">
    <visual>
      <material>
        <ambient>0.5 0.5 0.5 1.0</ambient>
        <diffuse>0.5 0.5 0.5 1.0</diffuse>
        <specular>0.0 0.0 0.0 1.0</specular>
        <emissive>0.0 0.0 0.0 1.0</emissive>
      </material>
    </visual>
  </gazebo>
  <!-- Jump Plugin -->
  <gazebo>
    <plugin filename="ignition-gazebo-joint-position-controller-system" name="gz::sim::systems::JointPositionController">
      <joint_name>joint_rotation_engin_pull_engin</joint_name>
      <topic>jump_cmd</topic>
      <p_gain>50</p_gain>
      <i_gain>1.0</i_gain>
      <d_gain>0.0</d_gain>
      <i_max>1</i_max>
      <i_min>-1</i_min>
      <cmd_max>1000</cmd_max>
      <cmd_min>-1000</cmd_min>
    </plugin>
  </gazebo>
  <!-- movement Plugins for arms-->
  <gazebo>
    <plugin filename="ignition-gazebo-joint-controller-system" name="gz::sim::systems::JointController">
      <topic>rot1_cmd</topic>
      <initial_velocity>0</initial_velocity>
      <joint_name>joint_pull_engin_rotating_arm1</joint_name>
      <use_force_commands>false</use_force_commands>
    </plugin>
  </gazebo>
  <gazebo>
    <plugin filename="ignition-gazebo-joint-controller-system" name="gz::sim::systems::JointController">
      <topic>rot2_cmd</topic>
      <initial_velocity>0</initial_velocity>
      <joint_name>joint_pull_engin_rotating_arm2</joint_name>
      <use_force_commands>false</use_force_commands>
    </plugin>
  </gazebo>
  <!-- Rotate center Plugin -->
  <gazebo>
    <plugin filename="ignition-gazebo-joint-position-controller-system" name="gz::sim::systems::JointPositionController">
      <joint_name>joint_outer_ball_rotation_engin</joint_name>
      <topic>turn_cmd</topic>
      <p_gain>1</p_gain>
      <i_gain>0.01</i_gain>
      <d_gain>0.3</d_gain>
      <i_max>1</i_max>
      <i_min>-1</i_min>
      <cmd_max>1000</cmd_max>
      <cmd_min>-1000</cmd_min>
    </plugin>
  </gazebo>
  <!-- Get Position Plugin-->
  <gazebo>
    <plugin filename="ignition-gazebo-pose-publisher-system" name="gz::sim::systems::PosePublisher">
      <publish_link_pose>true</publish_link_pose>
      <publish_collision_pose>false</publish_collision_pose>
      <publish_visual_pose>false</publish_visual_pose>
      <publish_nested_model_pose>false</publish_nested_model_pose>
      <use_pose_vector_msg>true</use_pose_vector_msg>
      <update_frequency>1</update_frequency>
    </plugin>
  </gazebo>
  <!-- Get Join state-->
  <gazebo>
    <plugin filename="ignition-gazebo-pose-publisher-system" name="gz::sim::systems::PosePublisher">
      <publish_link_pose>true</publish_link_pose>
      <publish_collision_pose>false</publish_collision_pose>
      <publish_visual_pose>false</publish_visual_pose>
      <publish_nested_model_pose>false</publish_nested_model_pose>
      <use_pose_vector_msg>true</use_pose_vector_msg>
    </plugin>
  </gazebo>
  <link name="outer_ball">
    <inertial>
      <mass value="0.5"/>
      <inertia ixx="0.064" ixy="0" ixz="0" iyy="0.064" iyz="0" izz="0.064"/>
    </inertial>
    <collision>
      <geometry>
        <sphere radius="0.44"/>
      </geometry>
    </collision>
    <visual>
      <geometry>
        <sphere radius="0.44"/>
      </geometry>
    </visual>
  </link>
  <!-- Joint - rotation_engin / pull_engin -->
  <joint name="joint_rotation_engin_pull_engin" type="prismatic">
    <origin rpy="0 0 0" xyz="0 0 0"/>
    <child link="pull_engin"/>
    <parent link="rotation_engin"/>
    <axis rpy="0 0 0" xyz="0 0 1"/>
    <limit effort="10000" lower="-0.4" upper="0" velocity="1000"/>
  </joint>
  <!-- Link - pull_engin -->
  <link name="pull_engin">
    <inertial>
      <mass value="1.2"/>
      <inertia ixx="0.001" ixy="0" ixz="0" iyy="0.001" iyz="0" izz="0.001"/>
    </inertial>
    <collision name="collision">
      <geometry>
        <sphere radius="0.05"/>
      </geometry>
    </collision>
    <visual>
      <geometry>
        <sphere radius="0.05"/>
      </geometry>
    </visual>
  </link>
  <!-- Joint - outer_ball /  rotation engin-->
  <joint name="joint_outer_ball_rotation_engin" type="continuous">
    <origin rpy="0 0 0" xyz="0 0 0"/>
    <child link="rotation_engin"/>
    <parent link="outer_ball"/>
    <axis rpy="0 0 0" xyz="0 0 1"/>
    <limit effort="10000" velocity="5"/>
    <joint_properties damping="1.0" friction="1.0"/>
  </joint>
  <link name="rotation_engin">
    <inertial>
      <mass value="1.2"/>
      <origin rpy="0 0 0" xyz="0 0 0"/>
      <inertia ixx="0.0538" ixy="0" ixz="0" iyy="0.0538" iyz="0" izz="0.00106"/>
    </inertial>
    <collision>
      <geometry>
        <box size="0.08 0.08 0.87"/>
      </geometry>
    </collision>
    <visual>
      <geometry>
        <box size="0.08 0.08 0.87"/>
      </geometry>
    </visual>
  </link>
  <!-- Joint - pull_engin /  rotating_arms-->
  <joint name="joint_pull_engin_rotating_arm1" type="continuous">
    <origin rpy="3.141 0 0" xyz="-0.055 0 0"/>
    <child link="rotating_arm1"/>
    <parent link="pull_engin"/>
    <axis rpy="0 0 0" xyz="1 0 0">
      <dynamics>
        <friction>1</friction>
      </dynamics>
    </axis>
    <limit effort="10000" velocity="100"/>
  </joint>
  <link name="rotating_arm1">
    <inertial>
      <mass value="3.2"/>
      <origin rpy="0 0 0" xyz="-0 0 0.18"/>
      <inertia ixx="0.0116" ixy="0" ixz="0" iyy="0.0108" iyz="0" izz="0.000842"/>
    </inertial>
    <collision>
      <origin rpy="0 0 0" xyz="-0 0 0.18"/>
      <geometry>
        <box size="0.01 0.1 0.36"/>
      </geometry>
    </collision>
    <visual>
      <origin rpy="0 0 0" xyz="-0 0 0.18"/>
      <geometry>
        <box size="0.01 0.1 0.36"/>
      </geometry>
    </visual>
  </link>
  <joint name="joint_pull_engin_rotating_arm2" type="continuous">
    <origin rpy="3.141 0 0" xyz="0.055 0 0"/>
    <child link="rotating_arm2"/>
    <parent link="pull_engin"/>
    <axis rpy="0 0 0" xyz="1 0 0">
      <dynamics>
        <friction>1</friction>
      </dynamics>
    </axis>
    <limit effort="10000" velocity="100"/>
  </joint>
  <link name="rotating_arm2">
    <inertial>
      <mass value="3.2"/>
      <origin rpy="0 0 0" xyz="-0 0 0.18"/>
      <inertia ixx="0.0116" ixy="0" ixz="0" iyy="0.0108" iyz="0" izz="0.000842"/>
    </inertial>
    <collision>
      <origin rpy="0 0 0" xyz="-0 0 0.18"/>
      <geometry>
        <box size="0.01 0.1 0.36"/>
      </geometry>
    </collision>
    <visual>
      <origin rpy="0 0 0" xyz="-0 0 0.18"/>
      <geometry>
        <box size="0.01 0.1 0.36"/>
      </geometry>
    </visual>
  </link>
</robot>
